Workbook

Sheet Assessment
A1: BEST Maturity Assessment v2 — Scoring Sheet
A2: Terminal: | C2: Assessor(s): | E2: Date:
A4: 1. Leadership & Commitment
A5: Definition: The degree to which leaders at every tier personally own, model, resource and hold the organization accountable for the BEST operating system, rather than delegating it. | Construct measured: Visible, resourced, accountable leadership ownership of BEST.
A6: Item | B6: Statement (score the degree this is TRUE) | C6: Primary evidence | D6: Behavioural anchors (1 → 5) | E6: Score | F6: Evidence type | G6: Evidence note / examples
A7: 1.1 | B7: Senior leaders personally participate in BEST routines (gemba walks, tier reviews) on a published cadence, and their attendance is recorded. | C7: Data/Record: Gemba/tier-review attendance log for the last 3 months showing named senior leaders and dates. | D7: 1 – No leader attends BEST routines. 2 – Leaders attend occasionally when prompted; no cadence or record. 3 – A cadence exists and most scheduled attendances are met and logged. 4 – Attendance is ≥80% to plan, logged, and leaders act on what they see. 5 – Leaders drive the cadence, coach in-routine, and the practice is copied by other sites.
A8: 1.2 | B8: BEST principles are written into the terminal's stated vision/values and are reproduced accurately by leaders when asked. | C8: Document: Vision/values artefact referencing BEST; compare with 3 leader interviews. | D8: 1 – BEST appears in no leadership communication. 2 – Mentioned in documents but leaders cannot articulate it. 3 – Documented and most leaders can explain it consistently. 4 – Documented, explained, and visibly used to justify decisions. 5 – Lived language; leaders teach it to others and reference it spontaneously.
A9: 1.3 | B9: Leaders coach BEST behaviours during work (observed), rather than only directing or correcting outcomes. | C9: Observation: Observe ≥1 leader interaction in a routine; note coaching vs. telling behaviours. | D9: 1 – No coaching observed; command-and-control only. 2 – Occasional coaching by isolated individuals. 3 – Coaching observed in standard routines across most leaders. 4 – Structured coaching with follow-up; staff confirm it happens. 5 – Coaching culture; leaders develop other coaches.
A10: 1.4 | B10: A governance structure assigns named accountability for BEST results and meets on a defined cadence with minutes. | C10: Document: Governance ToR + last 2 meeting minutes with attendance and decisions. | D10: 1 – No governance for BEST. 2 – Informal/ad-hoc discussion, no terms or record. 3 – Defined governance with cadence and minutes. 4 – Governance tracks actions to closure and escalates. 5 – Governance drives strategy and is benchmarked across sites.
A11: 1.5 | B11: Leaders allocate dedicated resource (named time, budget line, or headcount) to BEST, evidenced in plans or budgets. | C11: Document: Budget line, role description, or time allocation showing committed BEST resource. | D11: 1 – No resource allocated. 2 – Resource borrowed ad hoc when crises allow. 3 – Defined resource committed for the year. 4 – Resource committed, tracked, and protected against reallocation. 5 – Resourcing model is proactive and replicated as a standard.
A12: 1.6 | B12: BEST expectations appear in leaders' individual performance objectives/scorecards. | C12: Document: Sample leadership scorecard or objective sheet containing a BEST-linked measure. | D12: 1 – Not in any objective. 2 – Mentioned informally, not measured. 3 – In objectives for most leaders. 4 – In objectives, reviewed, and influences ratings. 5 – Cascaded through all tiers and tied to development/consequence.
A13: 1.7 | B13: Leaders take direct ownership of removing systemic barriers raised by teams, with a traceable action trail. | C13: Data/Record: Escalation/barrier log showing items owned and closed by leaders. | D13: 1 – Barriers are ignored or pushed back down. 2 – Some barriers addressed reactively, untracked. 3 – Barriers logged and most are actioned by leaders. 4 – Barriers tracked to closure with timeliness measured. 5 – Proactive barrier removal; root-cause patterns eliminated systemically.
A14: 1.8 | B14: Leadership messages on BEST are aligned across tiers (global/regional/terminal) with no contradiction reported by staff. | C14: Interview: Triangulate 3 tiers on the same priority; check for consistency. | D14: 1 – Tiers give conflicting messages. 2 – Alignment by chance, not design. 3 – Generally aligned across tiers. 4 – Deliberately aligned and reinforced in cascades. 5 – One coherent voice; alignment is self-correcting.
A15: 1.9 | B15: Leaders publicly recognize BEST contributions in their own routines (observed or recorded), not only via HR programs. | C15: Observation: Observe or evidence a leader-led recognition act tied to BEST behaviour. | D15: 1 – No leader recognition of BEST. 2 – Rare, generic praise. 3 – Regular, specific recognition by leaders. 4 – Recognition tied to behaviours and visible to teams. 5 – Recognition shapes culture and is emulated widely.
A16: 1.10 | B16: Frontline employees independently describe their leaders as role models for improvement (corroborated in interview). | C16: Interview: Ask ≥3 frontline staff to describe leadership behaviour unprompted. | D16: 1 – Staff see leaders as disengaged. 2 – Mixed perceptions; depends on individual. 3 – Most staff view leaders positively on improvement. 4 – Staff give concrete examples of role-modelling. 5 – Leaders are cited as the reason improvement endures.
A17: Element 1 score (avg of scored items × 20, 0–100) | E17: =IFERROR(ROUND(AVERAGEIF(E7:E16,">0")*20,0),0) -> 0 | F17: =IF($E$17=0,"—",IF($E$17<=20,"Absent",IF($E$17<=40,"Emerging",IF($E$17<=60,"Established",IF($E$17<=80,"Integrated","Best-in-class"))))) -> —
A19: 2. Strategy Deployment
A20: Definition: The degree to which corporate strategy is translated, cascaded, owned and reviewed down to terminal and team level through a structured (Hoshin-type) process. | Construct measured: Line-of-sight from corporate strategy to team action, with review and adaptation.
A21: Item | B21: Statement (score the degree this is TRUE) | C21: Primary evidence | D21: Behavioural anchors (1 → 5) | E21: Score | F21: Evidence type | G21: Evidence note / examples
A22: 2.1 | B22: A structured method (e.g., Hoshin/X-matrix) cascades corporate strategy into terminal-level plans, and the artefact exists. | C22: Document: Deployment matrix or cascade map linking corporate goals to terminal objectives. | D22: 1 – No cascade method. 2 – Goals shared as a list, not cascaded. 3 – Structured cascade exists for the terminal. 4 – Cascade is reviewed and adjusted each cycle. 5 – Cascade is two-way (catchball) and continuously refined.
A23: 2.2 | B23: Strategic initiatives are explicitly prioritized against value and capacity, with a documented rationale. | C23: Document: Prioritized initiative list with criteria/scoring. | D23: 1 – No prioritization. 2 – Implicit prioritization in someone's head. 3 – Documented prioritization criteria applied. 4 – Prioritization revisited as conditions change. 5 – Portfolio actively balanced; low-value work stopped.
A24: 2.3 | B24: Every team has KPIs that trace upward to a strategic objective, visible on a deployment board. | C24: Observation: Team board showing KPI-to-objective linkage. | D24: 1 – No team KPIs linked to strategy. 2 – Some KPIs, no linkage shown. 3 – Most teams show linked KPIs. 4 – Linkage used in reviews to steer work. 5 – Teams adjust their own KPIs as strategy shifts.
A25: 2.4 | B25: Progress against strategic goals is reviewed on a fixed cadence at each tier, with the review recorded. | C25: Data/Record: Review minutes/board photos across at least 2 tiers for last cycle. | D25: 1 – No reviews. 2 – Irregular reviews when problems surface. 3 – Fixed-cadence reviews at each tier. 4 – Reviews drive countermeasures and are minuted. 5 – Reviews predictively adjust the plan; self-running.
A26: 2.5 | B26: A sampled employee can explain how their daily work contributes to a strategic goal. | C26: Interview: Ask ≥3 staff to connect their work to a terminal objective. | D26: 1 – No awareness of strategy. 2 – Vague awareness, no personal link. 3 – Most can state the link generally. 4 – Most give a concrete personal example. 5 – Staff use the link to make daily trade-offs.
A27: 2.6 | B27: Each initiative has a single named owner and an accountability mechanism (review or scorecard). | C27: Document: Initiative register with owners and review mechanism. | D27: 1 – No owners. 2 – Shared/unclear ownership. 3 – Single owners assigned for most. 4 – Owners held accountable in reviews. 5 – Ownership culture; owners self-escalate risks.
A28: 2.7 | B28: Mid-cycle corrections are made and documented when initiatives go off-track. | C28: Data/Record: Evidence of a re-planned or stopped initiative with rationale. | D28: 1 – Plans never change regardless of results. 2 – Changes happen but undocumented. 3 – Corrections made and recorded. 4 – Corrections are timely and data-triggered. 5 – Adaptation is routine and anticipatory.
A29: 2.8 | B29: Resources (people, budget, time) are formally assigned to strategic initiatives, not assumed. | C29: Document: Resourcing plan attached to initiatives. | D29: 1 – No resourcing. 2 – Resourcing implicit. 3 – Resourcing documented for most. 4 – Resourcing tracked vs. consumption. 5 – Resourcing optimized across the portfolio.
A30: 2.9 | B30: Strategy deployment is synchronized with the annual business-planning calendar (defined dates). | C30: Document: Planning calendar showing deployment milestones. | D30: 1 – Disconnected from planning cycle. 2 – Loosely timed, often late. 3 – Synced to the annual cycle. 4 – Synced and feeds budgeting decisions. 5 – Fully integrated rolling planning.
A31: 2.10 | B31: Regional/global initiatives and local execution are reconciled so there is no duplicated or conflicting work (verified). | C31: Interview: Cross-check 1 regional initiative against local plan for conflict. | D31: 1 – Local and regional plans conflict. 2 – Conflicts found and resolved late. 3 – Generally reconciled. 4 – Deliberately reconciled each cycle. 5 – Seamless global-to-local flow.
A32: Element 2 score (avg of scored items × 20, 0–100) | E32: =IFERROR(ROUND(AVERAGEIF(E22:E31,">0")*20,0),0) -> 0 | F32: =IF($E$32=0,"—",IF($E$32<=20,"Absent",IF($E$32<=40,"Emerging",IF($E$32<=60,"Established",IF($E$32<=80,"Integrated","Best-in-class"))))) -> —
A34: 3. Standard Work & Daily Management
A35: Definition: The degree to which work is standardized and managed through disciplined daily routines (tiered huddles, visual management, escalation) that surface and resolve deviations. | Construct measured: Standardized work executed and governed through a tiered daily management system.
A36: Item | B36: Statement (score the degree this is TRUE) | C36: Primary evidence | D36: Behavioural anchors (1 → 5) | E36: Score | F36: Evidence type | G36: Evidence note / examples
A37: 3.1 | B37: Tiered daily huddles run to a fixed schedule at each operational level (observed running, not just scheduled). | C37: Observation: Observe at least one tier huddle; confirm time, attendance, duration. | D37: 1 – No daily huddles. 2 – Huddles happen only when a manager calls them. 3 – Scheduled huddles run at most tiers. 4 – Huddles run to plan and start/end on time daily. 5 – Tiered system self-runs and is taught to new sites.
A38: 3.2 | B38: Teams review live KPIs against target during the huddle and can explain the current trend. | C38: Observation: Confirm KPI board is current and team explains a trend. | D38: 1 – No KPIs in huddle. 2 – KPIs shown but stale or unexplained. 3 – Current KPIs reviewed at target level. 4 – Trends drive in-huddle decisions. 5 – Teams self-correct from trend signals.
A39: 3.3 | B39: A standard agenda/structure for the huddle is defined and followed. | C39: Document: Standard huddle agenda + observed adherence. | D39: 1 – No agenda. 2 – Agenda exists on paper only. 3 – Agenda followed most days. 4 – Agenda followed and improved by the team. 5 – Agenda is a benchmark standard.
A40: 3.4 | B40: Deviations from plan are identified in the huddle and escalated through a defined path. | C40: Document: Escalation chart + an example escalated item. | D40: 1 – Deviations not surfaced. 2 – Surfaced but not escalated. 3 – Defined escalation used for most. 4 – Escalation is timely and closed-loop. 5 – Escalation prevents recurrence systemically.
A41: 3.5 | B41: Actions from huddles have a named owner and due date and are tracked to closure. | C41: Data/Record: Action log showing owner, date, closure status. | D41: 1 – No actions captured. 2 – Actions captured, not tracked. 3 – Owner+date assigned for most. 4 – Closure rate tracked and reviewed. 5 – High on-time closure sustained; root causes removed.
A42: 3.6 | B42: Leaders attend and coach within daily routines (observed), reinforcing the standard. | C42: Observation: Observe leader behaviour in a routine. | D42: 1 – Leaders absent from routines. 2 – Leaders attend passively. 3 – Leaders attend and reinforce standard. 4 – Leaders coach and develop the team. 5 – Leaders grow coaches; routine improves itself.
A43: 3.7 | B43: Visual management at the workplace makes status, standards and abnormalities obvious at a glance. | C43: Observation: Photograph/observe visual management boards in use. | D43: 1 – No visual management. 2 – Boards exist but unused/outdated. 3 – Boards current and used in routines. 4 – Visuals trigger action when abnormal. 5 – Visual system is exemplary and copied.
...

Sheet Dashboard
B2: BEST Maturity — Results Dashboard
A4: # | B4: Element | C4: Score | D4: Band | E4: Gap to 100 | F4: Priority (lowest scored first)
A5: 1 | B5: Leadership & Commitment | C5: =Assessment!E17 -> 0 | D5: =IF(C5=0,"—",IF(C5<=20,"Absent",IF(C5<=40,"Emerging",IF(C5<=60,"Established",IF(C5<=80,"Integrated","Best-in-class"))))) -> — | E5: =100-C5 -> 100
A6: 2 | B6: Strategy Deployment | C6: =Assessment!E32 -> 0 | D6: =IF(C6=0,"—",IF(C6<=20,"Absent",IF(C6<=40,"Emerging",IF(C6<=60,"Established",IF(C6<=80,"Integrated","Best-in-class"))))) -> — | E6: =100-C6 -> 100
A7: 3 | B7: Standard Work & Daily Management | C7: =Assessment!E47 -> 0 | D7: =IF(C7=0,"—",IF(C7<=20,"Absent",IF(C7<=40,"Emerging",IF(C7<=60,"Established",IF(C7<=80,"Integrated","Best-in-class"))))) -> — | E7: =100-C7 -> 100
A8: 4 | B8: Problem Solving & Continuous Improvement | C8: =Assessment!E62 -> 0 | D8: =IF(C8=0,"—",IF(C8<=20,"Absent",IF(C8<=40,"Emerging",IF(C8<=60,"Established",IF(C8<=80,"Integrated","Best-in-class"))))) -> — | E8: =100-C8 -> 100
A9: 5 | B9: Process & Performance Management | C9: =Assessment!E77 -> 0 | D9: =IF(C9=0,"—",IF(C9<=20,"Absent",IF(C9<=40,"Emerging",IF(C9<=60,"Established",IF(C9<=80,"Integrated","Best-in-class"))))) -> — | E9: =100-C9 -> 100
A10: 6 | B10: Recognition & Culture | C10: =Assessment!E92 -> 0 | D10: =IF(C10=0,"—",IF(C10<=20,"Absent",IF(C10<=40,"Emerging",IF(C10<=60,"Established",IF(C10<=80,"Integrated","Best-in-class"))))) -> — | E10: =100-C10 -> 100
A11: 7 | B11: Capability Building | C11: =Assessment!E107 -> 0 | D11: =IF(C11=0,"—",IF(C11<=20,"Absent",IF(C11<=40,"Emerging",IF(C11<=60,"Established",IF(C11<=80,"Integrated","Best-in-class"))))) -> — | E11: =100-C11 -> 100
A12: 8 | B12: Best Practice Sharing & Knowledge Management | C12: =Assessment!E122 -> 0 | D12: =IF(C12=0,"—",IF(C12<=20,"Absent",IF(C12<=40,"Emerging",IF(C12<=60,"Established",IF(C12<=80,"Integrated","Best-in-class"))))) -> — | E12: =100-C12 -> 100
A13: 9 | B13: Customer Experience (CX) | C13: =Assessment!E137 -> 0 | D13: =IF(C13=0,"—",IF(C13<=20,"Absent",IF(C13<=40,"Emerging",IF(C13<=60,"Established",IF(C13<=80,"Integrated","Best-in-class"))))) -> — | E13: =100-C13 -> 100
A14: 10 | B14: Safety Excellence | C14: =Assessment!E152 -> 0 | D14: =IF(C14=0,"—",IF(C14<=20,"Absent",IF(C14<=40,"Emerging",IF(C14<=60,"Established",IF(C14<=80,"Integrated","Best-in-class"))))) -> — | E14: =100-C14 -> 100
A15: OVERALL MATURITY (avg of elements) | C15: =IFERROR(ROUND(AVERAGEIF(C5:C14,">0"),0),0) -> 0 | D15: =IF(C15=0,"—",IF(C15<=20,"Absent",IF(C15<=40,"Emerging",IF(C15<=60,"Established",IF(C15<=80,"Integrated","Best-in-class"))))) -> —
B18: Interpretation bands
B19: 0–20 | C19: Absent
B20: 21–40 | C20: Emerging
B21: 41–60 | C21: Established
B22: 61–80 | C22: Integrated
B23: 81–100 | C23: Best-in-class
